Workbook

Sheet RESUMEN
D2: TRANSPORTE MONTIVERO
D3: CLIENTE: | F3: TERSUAVE/ DISAL S.A.
E5: PERIODO: | F5: 1º QUINCENA ENERO 2026
F6: DEL 27 DIC. AL 15 ENERO
A9: VIAJES EN MOVILES | D9: KM | G9: RECORRIDOS EN TRAFIC | J9: =TRAFIC!E2 -> 94
A10: CIUDAD | D10: ='RECORRIDO CIUDAD'!G3 -> 5476.7283
A11: CADETERIA | D11: =CADETERIA!G3 -> 165.62
A12: JUSTO DARACT | D12: ='JUSTO DARACT'!H3 -> 1757
A13: SAN LUIS | D13: ='SAN LUIS'!H3 -> 757.66
B14: TOTAL | D14: =SUM(D10:D13) -> 8157.0083
A22: NOVEDADES
A23: TARIFA NUEVA: ENERO-DICIEMBRE-FEBRERO 2026

Sheet RECORRIDO CIUDAD
E3: Total de Km: | G3: =F559 -> 5476.7283
E4: Costo Total:
A7: N° | B7: Nº BOLETA | C7: FECHA | D7: HORARIO | F7: KM REALIZADOS | G7: PASAJEROS | H7: LLEGADA A PLANTA | I7: MOTIVO | J7: ESPERA | K7: OBSERVACIONES | L7: CHOFER
D8: ENTRADA | E8: SALIDA
A9: 1 | B9: 133949 | C9: 46385 | D9: 0.25 | F9: 8.5 | G9: GARRIDO-LUCERO | H9: 0.24305556 | I9: INGRESO | L9: GABRIEL PONCE
A10: 2 | B10: 133950 | C10: 46385 | D10: 0.29166667 | F10: 9.3 | G10: FALCON-RITTANO-ROMAN | H10: 0.28402778 | I10: INGRESO | L10: GABRIEL PONCE
A11: 3 | B11: 133951 | C11: 46385 | D11: 0.58333333 | F11: 9.5 | G11: MONDON-BUSTOS-GUTIERREZ | H11: 0.57361111 | I11: INGRESO | L11: GABRIEL PONCE
A12: 4 | B12: 133952 | C12: 46379 | D12: 0.625 | F12: 9 | G12: MERCAU J. | H12: 0.61944444 | I12: INGRESO | L12: GABRIEL PONCE
A13: 5 | B13: 133953 | C13: 46051 | E13: 0.625 | F13: 14.1 | G13: AGÜERO-CHAVEZ-TEJERO | I13: EGRESO | L13: GABRIEL PONCE
A14: 6 | B14: 133954 | C14: 46385 | E14: 0.66666667 | F14: 9 | G14: LARROUDE-BRUÑA | I14: EGRESO | L14: GABRIEL PONCE
A15: 7 | B15: 133686 | C15: 46021 | E15: 0.25 | F15: 14.5 | G15: ILLANES-FUNES C.-ZAVALA | I15: EGRESO | L15: GABRIEL PONCE
A16: 8 | B16: 133687 | C16: 46021 | D16: 0.29166667 | F16: 9.3 | G16: ROMAN-RITTANO-FALCON | H16: 0.28402778 | I16: INGRESO | L16: GABRIEL PONCE
A17: 9 | B17: 133688 | C17: 46021 | D17: 0.375 | F17: 7 | G17: LUCERO P. | H17: 0.36805556 | I17: INGRESO | L17: GABRIEL PONCE
A18: 10 | B18: 133689 | C18: 46021 | E18: 0.375 | F18: 10 | G18: OLGUIN J. | I18: EGRESO | L18: GABRIEL PONCE
A19: 11 | B19: 133697 | C19: 46021 | E19: 0.083333333 | F19: 8.8 | G19: CAPUSOTTI-SEGURA-FUNES | I19: EGRESO | L19: GABRIEL PONCE
A20: 12 | B20: 133691 | C20: 46027 | D20: 0.20833333 | F20: 10.8 | G20: SALAFIA-FLORES | H20: 0.19375 | I20: INGRESO | L20: GABRIEL PONCE
A21: 13 | B21: 133693 | C21: 46027 | D21: 0.29166667 | F21: 11 | G21: GOMEZ-TISERA-ALTURRIA | H21: 0.28680556 | I21: INGRESO | L21: GABRIEL PONCE
A22: 14 | B22: 133694 | C22: 46027 | E22: 0.95833333 | F22: 10.8 | G22: VEGA-PEDERNERA | I22: EGRESO | L22: GABRIEL PONCE
A23: 15 | B23: 133695 | C23: 46028 | E23: 0 | F23: 7 | G23: TORRES L. | I23: EGRESO | L23: GABRIEL PONCE
A24: 16 | B24: 133696 | C24: 46028 | E24: 0.041666667 | F24: 11.5 | G24: SEGURA-MERCAU-FUNES L. | I24: EGRESO | L24: GABRIEL PONCE
A25: 17 | B25: 133886 | C25: 46028 | E25: 0.25 | F25: 14.6 | G25: OLGUIN-SOMBRA-MATURANO-TORRES | I25: EGRESO | L25: GABRIEL PONCE
A26: 18 | B26: 133698 | C26: 46028 | D26: 0.54166667 | F26: 9.5 | G26: FUNES M.-SEGURA-CAPUSOTTI-HOYOS | H26: 0.53333333 | I26: INGRESO | L26: GABRIEL PONCE
A27: 19 | B27: 133887 | C27: 46028 | D27: 0.58333333 | F27: 17 | G27: ZAVALA-ALTAMIRANO | H27: 0.58055556 | I27: INGRESO | L27: GABRIEL PONCE
A28: 20 | B28: 133888 | C28: 46332 | E28: 0.66666667 | F28: 10 | G28: TISERA-GOMEZ | I28: EGRESO | L28: GABRIEL PONCE
A29: 21 | B29: 133699 | C29: 46028 | E29: 0.70833333 | F29: 11.7 | G29: SHORTREDE-VIDELA-GARRO | I29: EGRESO | L29: GABRIEL PONCE
A30: 22 | B30: 133700 | C30: 46028 | D30: 0.75 | F30: 13 | G30: PAYERO-OCHOA | H30: 0.73819444 | I30: INGRESO | L30: GABRIEL PONCE
A31: 23 | B31: 136601 | C31: 46028 | E31: 0.75 | F31: 9 | G31: BUSTOS L. | I31: EGRESO | K31: NUEVO DOMICILIO: SALTA AL 1500 | L31: GABRIEL PONCE
A32: 24 | B32: 136602 | C32: 46028 | E32: 0.95833333 | F32: 10.8 | G32: VEGA-PEDERNERA | I32: EGRESO | L32: GABRIEL PONCE
A33: 25 | B33: 136603 | C33: 46029 | E33: 0 | F33: 10 | G33: TORRES-MERCAU | I33: EGRESO | L33: GABRIEL PONCE
A34: 26 | B34: 136604 | C34: 46029 | E34: 0.083333333 | F34: 13.5 | G34: DICRISTOFANO-CACERES-CHAVEZ-FUNES L. | I34: EGRESO | L34: GABRIEL PONCE
A35: 27 | B35: 136605 | C35: 46029 | D35: 0.25 | F35: 13.5 | G35: GARRIDO-TEJERO-POLLACHI | H35: 0.24236111 | I35: INGRESO | L35: GABRIEL PONCE
A36: 28 | B36: 136606 | C36: 46029 | E36: 0.25 | F36: 13.3 | G36: PAYERO-TORRES-OCHOA | I36: EGRESO | L36: GABRIEL PONCE
A37: 29 | B37: 136607 | C37: 46029 | D37: 0.29166667 | F37: 11 | G37: GOMEZ-TISERA-ALTURRIA | H37: 0.28472222 | I37: INGRESO | L37: GABRIEL PONCE
A38: 30 | B38: 136608 | C38: 46030 | E38: 0.083333333 | F38: 10.8 | G38: OZAN-CAPUSOTTI-FUNES L. | I38: EGRESO | L38: GABRIEL PONCE
A39: 31 | B39: 133609 | C39: 46030 | D39: 0.25 | F39: 13.5 | G39: GARRIDO-TEJERO-POLLACHI | H39: 0.24444444 | I39: INGRESO | L39: GABRIEL PONCE
A40: 32 | B40: 136610 | C40: 46030 | E40: 0.25 | F40: 14.5 | G40: NUÑEZ-PAYERO-TORRES-OCHOA | I40: EGRESO | L40: GABRIEL PONCE
A41: 33 | B41: 136611 | C41: 46030 | D41: 0.29166667 | F41: 11 | G41: GOMEZ-TISERA-ALTURRIA | H41: 0.28472222 | I41: INGRESO | L41: GABRIEL PONCE
A42: 34 | B42: 136612 | C42: 46030 | D42: 0.54166667 | F42: 7 | G42: HOYOS S. | H42: 0.53888889 | I42: INGRESO | L42: GABRIEL PONCE
A43: 35 | B43: 136614 | C43: 46030 | E43: 0.625 | F43: 13.5 | G43: GARRIDO-TEJERO-POLLACHI | I43: EGRESO | L43: GABRIEL PONCE
A44: 36 | B44: 136615 | C44: 46030 | E44: 0.70833333 | F44: 12 | G44: GUZMAN-AGUIRRE-NIEVAS | I44: EGRESO | L44: GABRIEL PONCE
...

Sheet CADETERIA
E3: Total de Km: | G3: =F19 -> 165.62
E4: Costo Total:
A7: N° | B7: Nº BOLETA | C7: FECHA | D7: HORARIO | F7: KM REALIZADOS | G7: MIN. ESPERA | H7: DETALLE | I7: CHOFER
D8: ENTRADA | E8: SALIDA
A9: 1 | B9: 133522 | C9: 46031 | D9: 0.5 | F9: 8 | G9: 15 | H9: ESCRIBANIA-CLINICA-PLANTA | I9: JORGE ICARDI
A10: 2 | B10: 134006 | C10: 46021 | D10: 15.30 | F10: 6 | H10: ESCRIBANIA-PLANTA | I10: EZEQUIEL VERGARA
A11: 3 | B11: 134014 | C11: 46027 | D11: 11.00 | F11: 6 | H11: ESCRIBANIA-PLANTA | I11: EZEQUIEL VERGARA
A12: 4 | B12: 134036 | C12: 46030 | D12: 11.30 | F12: 6 | H12: ESCRIBANIA-PLANTA | I12: EZEQUIEL VERGARA
A13: 5 | B13: 134037 | C13: 46030 | D13: 11.40 | F13: 12.8 | G13: 20 | H13: PLANTA-HIDRAULICA-PLANTA | I13: EZEQUIEL VERGARA
A14: 6 | B14: 134206 | C14: 46035 | E14: 0.45833333 | F14: 6.5 | H14: ESCRIBANIA: PLANTA - CIUDAD | I14: SERGIO FERNANDEZ
A15: 7 | B15: 136468 | C15: 46035 | E15: 0.45138889 | F15: 108.5 | H15: LLEVAR MUESTRAS: PLANTA VM - COLORIN | I15: DANIEL DUTREY
A16: 8 | B16: 136480 | C16: 46037 | D16: 0.52083333 | F16: 6 | H16: BULONERA CENTRO-PLANTA | I16: DANIEL DUTREY
F17: =SUM(F9:F16) -> 159.8 | G17: =SUM(G9:G16) -> 35
C18: 20 Min. De espera equivalente en KM | F18: 5.82
D19: TOTAL DE KM | F19: =SUM(F17:F18) -> 165.62

Sheet JUSTO DARACT
E3: Total de Km: | H3: =G47 -> 1757
E4: Costo Total:
A7: N° | B7: Nº BOLETA | C7: FECHA | D7: HORARIO | F7: LLEGADA PLANTA | G7: KM REALIZADOS | H7: PASAJEROS | I7: ESPERA | J7: OBSERVACIONES | K7: CHOFER
D8: ENTRADA | E8: SALIDA
A9: 1 | B9: 133685 | C9: 46021 | D9: 0.25 | F9: 0.24027778 | G9: 50 | H9: MIDLELL-BELLO-DOMINGUEZ | J9: INGRESO | K9: GABRIEL PONCE
A10: 2 | B10: 133692 | C10: 46027 | D10: 0.25 | F10: 0.24305556 | G10: 50 | H10: BELLO J. | J10: INGRESO | K10: GABRIEL PONCE
A11: 3 | B11: 133885 | C11: 46028 | D11: 0.25 | F11: 0.24305556 | G11: 50 | H11: BELLO J. | J11: INGRESO | K11: GABRIEL PONCE
A12: 4 | B12: 136440 | C12: 46028 | D12: 0.625 | F12: 0.62013889 | G12: 50 | H12: DOMINGUEZ D. | J12: INGRESO | K12: GABRIEL PONCE
A13: 5 | B13: 133613 | C13: 46030 | D13: 0.625 | F13: 0.61319444 | G13: 50 | H13: DOMINGUEZ D. | J13: INGRESO | K13: GABRIEL PONCE
A14: 6 | B14: 133618 | C14: 46031 | E14: 0 | G14: 50 | H14: DOMINGUEZ D. | J14: EGRESO | K14: GABRIEL PONCE
A15: 7 | B15: 136623 | C15: 46031 | D15: 0.58333333 | F15: 0.57083333 | G15: 50 | H15: DOMINGUEZ D. | J15: INGRESO | K15: GABRIEL PONCE
A16: 8 | B16: 136625 | C16: 46031 | E16: 0.91666667 | G16: 50 | H16: DOMINGUEZ D. | J16: EGRESO | K16: GABRIEL PONCE
A17: 9 | B17: 136630 | C17: 46034 | D17: 0.25 | F17: 0.24444444 | G17: 50 | H17: BELLO-DOMINGUEZ | J17: INGRESO | K17: GABRIEL PONCE
A18: 10 | B18: 133543 | C18: 46036 | E18: 0.70833333 | G18: 50 | H18: BELLO-DOMINGUEZ | J18: EGRESO | K18: GABRIEL PONCE
A19: 11 | B19: 136637 | C19: 46037 | D19: 0.25 | F19: 0.23958333 | G19: 50 | H19: BELLO-DOMINGUEZ | J19: INGRESO | K19: GABRIEL PONCE
A20: 12 | B20: 133958 | C20: 46387 | E20: 0.54166667 | G20: 50 | H20: MIDLELL-BELLO-DOMINGUEZ | J20: EGRESO | K20: EVELIN ROJAS
A21: 13 | B21: 133969 | C21: 46028 | E21: 0.625 | G21: 50 | H21: BELLO J. | J21: EGRESO | K21: EVELIN ROJAS
A22: 14 | B22: 136801 | C22: 46035 | E22: 0.625 | G22: 50 | H22: DOMINGUEZ-BELLO | J22: EGRESO | K22: EVELIN ROJAS
A23: 15 | B23: 133453 | C23: 46020 | D23: 06.00 | F23: 05.51 | G23: 50 | H23: MIDLELL-BELLO-DOMINGUEZ | J23: INGRESO | K23: PABLO ALCARAZ
A24: 16 | B24: 136296 | C24: 46020 | E24: 15.00 | G24: 50 | H24: MIDLELL-BELLO-DOMINGUEZ | J24: EGRESO | K24: PABLO ALCARAZ
A25: 17 | B25: 133470 | C25: 46022 | D25: 06.00 | F25: 05.51 | G25: 50 | H25: MIDLELL-BELLO-DOMINGUEZ | J25: INGRESO | K25: PABLO ALCARAZ
A26: 18 | B26: 134017 | C26: 46027 | E26: 15.00 | G26: 50 | H26: BELLO | J26: EGRESO | K26: PABLO ALCARAZ
A27: 19 | B27: 133478 | C27: 46027 | E27: 24.00 | G27: 50 | H27: DOMINGUEZ | J27: EGRESO | K27: PABLO ALCARAZ
A28: 20 | B28: 133484 | C28: 46028 | E28: 24.00 | G28: 50 | H28: DOMINGUEZ | J28: EGRESO | K28: PABLO ALCARAZ
A29: 21 | B29: 133485 | C29: 46029 | D29: 06.00 | F29: 05.51 | G29: 50 | H29: BELLO | J29: INGRESO | K29: PABLO ALCARAZ
A30: 22 | B30: 133491 | C30: 46029 | E30: 24.00 | G30: 50 | H30: DOMINGUEZ | J30: EGRESO | K30: PABLO ALCARAZ
A31: 23 | B31: 133492 | C31: 46030 | D31: 06.00 | F31: 05.46 | G31: 50 | H31: BELLO | J31: INGRESO | K31: PABLO ALCARAZ
A32: 24 | B32: 136719 | C32: 46035 | D32: 06.00 | F32: 06.00 | G32: 50 | H32: DOMINGUEZ-BELLO | J32: INGRESO | K32: PABLO ALCARAZ
A33: 25 | B33: 136727 | C33: 46036 | D33: 06.00 | F33: 05.50 | G33: 50 | H33: DOMINGUEZ-BELLO | J33: INGRESO | K33: PABLO ALCARAZ
A34: 26 | B34: 136501 | C34: 46027 | D34: 15.00 | F34: 14.48 | G34: 50 | H34: DOMINGUEZ | J34: INGRESO | K34: DAMIAN ISOLA
A35: 27 | B35: 136525 | C35: 46031 | E35: 16.00 | G35: 50 | H35: BELLO | J35: EGRESO | K35: DAMIAN ISOLA
A36: 28 | B36: 136545 | C36: 46037 | E36: 15.00 | G36: 50 | H36: DOMINGUEZ-BELLO | J36: EGRESO | K36: DAMIAN ISOLA
A37: 29 | B37: 133510 | C37: 46386 | E37: 0.70833333 | G37: 50 | H37: BELLO J. | J37: EGRESO | K37: JORGE ICARDI
A38: 30 | B38: 133520 | C38: 46031 | D38: 0.25 | F38: 0.23958333 | G38: 50 | H38: BELLO J. | J38: INGRESO | K38: JORGE ICARDI
A39: 31 | B39: 133530 | C39: 46034 | E39: 0.625 | G39: 50 | H39: BELLO-DOMINGUEZ | J39: EGRESO | K39: JORGE ICARDI
A40: 32 | B40: 136472 | C40: 46036 | E40: 0.625 | G40: 7 | H40: BELLO J. | J40: NEGATIVO EN EL EGRESO DE PLANTA | K40: JORGE ICARDI
A41: 33 | B41: 136316 | C41: 46029 | D41: 15.00 | F41: 14.46 | G41: 50 | H41: DOMINGUEZ | J41: INGRESO | K41: JUAN MOLINA
A42: 34 | B42: 134040 | C42: 46030 | E42: 15.00 | G42: 50 | H42: BELLO | J42: EGRESO | K42: EZEQUIEL VERGARA
A43: 35 | B43: 133873 | C43: 46021 | E43: 0.625 | G43: 50 | H43: MIDLELL-DOMINGUEZ | J43: EGRESO | K43: SERGIO FERNANDEZ
A44: 36 | B44: 133892 | C44: 46029 | E44: 0.70833333 | G44: 50 | H44: BELLO J. | J44: EGRESO | K44: SERGIO FERNANDEZ
...

Sheet SAN LUIS
E3: Total de Km: | H3: =G17 -> 757.66
E4: Costo Total:
A7: N° | B7: Nº BOLETA | C7: FECHA | D7: HORARIO | F7: LLEGADA PLANTA | G7: KM REALIZADOS | H7: PASAJEROS | I7: ESPERA | J7: OBSERVACIONES | K7: CHOFER
D8: ENTRADA | E8: SALIDA
A9: 1 | B9: 136620 | C9: 46031 | D9: 0.27083333 | G9: 107 | H9: CARENA LUCIA: DOMICILIO VM - COLORIN | J9: INGRESO COLORIN | K9: GABRIEL PONCE
A10: 2 | B10: 136635 | C10: 46035 | E10: 0.33333333 | G10: 209 | H10: ROLON M.-ANDURELL A.: PLANTA V.M. - MATRICERIA ARG. | I10: 90 | J10: IDA Y VUELTA A PLANTA CON ESPERA | K10: GABRIEL PONCE
A11: 3 | B11: 136636 | C11: 46036 | E11: 0.6875 | G11: 105 | H11: SHORTREDE A.: COLORIN - DOMICILIO VM | J11: EGRESO COLORIN | K11: GABRIEL PONCE
A12: 4 | B12: 136711 | C12: 46034 | D12: 06.00 | G12: 105 | H12: SHORTREDE A.: DOMICILIO V.M-COLORIN S.L | J12: INGRESO COLORIN | K12: PABLO ALCARAZ
A13: 5 | B13: 136730 | C13: 46036 | D13: 08.00 | G13: 108.9 | H13: RIVERO D.: PLANTA V.M-COLORIN S.L | J13: INGRESO COLORIN | K13: PABLO ALCARAZ
A14: 6 | B14: 136732 | C14: 46036 | E14: 15.00 | G14: 108.9 | H14: RIVERO: COLORIN S.L-DOMICILIO VM | J14: EGRESO COLORIN | K14: PABLO ALCARAZ
F15: KM REALIZADOS | G15: =SUM(G9:G14) -> 743.8 | I15: =SUM(I9:I14) -> 90
D16: 0 Min. De espera equivalente en KM | G16: 13.86 | I16: ESPERA
E17: TOTAL DE KM | G17: =SUM(G15:G16) -> 757.66

Sheet TRAFIC
C2: CANTIDAD DE VIAJES | E2: =F35 -> 94
C3: Total de Km:
C4: Costo Total:
A7: RECORRIDOS COMBIS
A8: FECHA | B8: RECORRIDO 1 (MERCEDES SPRINTER) | D8: VIAJES CANTIDAD | E8: RECORRIDO 2 (RENAULT MASTER) | H8: VIAJES CANTIDAD
A9: 46020 | B9: 06:00 - 07:00 | D9: 2 | E9: 06:00 - 07:00 | H9: 2
B10: 15:00 - 16:00 | D10: 2 | E10: 15:00 - 16:00 | H10: 2
A11: 46021 | B11: 06:00 - 07:00 | D11: 2 | E11: 06:00 - 07:00 | H11: 2
B12: 15:00 - 16:00 | D12: 2 | E12: 15:00 - 16:00 | H12: 2
A13: 46022 | B13: 06:00 - 07:00 | D13: 2 | E13: 06:00 - 07:00 | H13: 2
B14: 0.54166667 | D14: 1 | E14: 0.54166667 | H14: 1
A15: 46027 | B15: 06:00 - 07:00 | D15: 2 | E15: 06:00 - 07:00 | H15: 2
B16: 15:00 - 16:00 | D16: 2 | E16: 15:00 - 16:00 | H16: 2
A17: 46028 | B17: 06:00 - 07:00 | D17: 2 | E17: 06:00 - 07:00 | H17: 2
B18: 15:00 - 16:00 | D18: 2 | E18: 15:00 - 16:00 | H18: 2
A19: 46029 | B19: 06:00 - 07:00 | D19: 2 | E19: 06:00 - 07:00 | H19: 2
B20: 15:00 - 16:00 | D20: 2 | E20: 15:00 - 16:00 | H20: 2
A21: 46030 | B21: 06:00 - 07:00 | D21: 2 | E21: 06:00 - 07:00 | H21: 2
B22: 15:00 - 16:00 | D22: 2 | E22: 15:00 - 16:00 | H22: 2
A23: 46031 | B23: 06:00 - 07:00 | D23: 2 | E23: 06:00 - 07:00 | H23: 2
B24: 14:00 - 15:00 | D24: 2 | E24: 14:00 - 15:00 | H24: 2
A25: 46034 | B25: 06:00 - 07:00 | D25: 2 | E25: 06:00 - 07:00 | H25: 2
B26: 15:00 - 16:00 | D26: 2 | E26: 15:00 - 16:00 | H26: 2
A27: 46035 | B27: 06:00 - 07:00 | D27: 2 | E27: 06:00 - 07:00 | H27: 2
B28: 15:00 - 16:00 | D28: 2 | E28: 15:00 - 16:00 | H28: 2
A29: 46036 | B29: 06:00 - 07:00 | D29: 2 | E29: 06:00 - 07:00 | H29: 2
B30: 15:00 - 16:00 | D30: 2 | E30: 15:00 - 16:00 | H30: 2
A31: 46037 | B31: 06:00 - 07:00 | D31: 2 | E31: 06:00 - 07:00 | H31: 2
B32: 15:00 - 16:00 | D32: 2 | E32: 15:00 - 16:00 | H32: 2
D33: =SUM(D9:D32) -> 47 | E33: TOTALES DE VIAJES | H33: =SUM(H9:H32) -> 47
F35: =D33+H33 -> 94
